<?xml version="1.0"?><robot name="creature">
	<link name="0">
		<visual>
			<geometry>
				<cylinder length="1.474515050194945" radius="0.3565403602733246"/>
			</geometry>
		</visual>
		<collision>
			<geometry>
				<cylinder length="1.474515050194945" radius="0.3565403602733246"/>
			</geometry>
		</collision>
		<inertial>
			<mass value="0.5888660009037009"/>
			<inertia ixx="0.03" iyy="0.03" izz="0.03" ixy="0" ixz="0" iyx="0"/>
		</inertial>
	</link>
	<link name="11">
		<visual>
			<geometry>
				<cylinder length="0.32081908219065847" radius="0.1284561824784013"/>
			</geometry>
		</visual>
		<collision>
			<geometry>
				<cylinder length="0.32081908219065847" radius="0.1284561824784013"/>
			</geometry>
		</collision>
		<inertial>
			<mass value="0.016631066011143343"/>
			<inertia ixx="0.03" iyy="0.03" izz="0.03" ixy="0" ixz="0" iyx="0"/>
		</inertial>
	</link>
	<link name="22">
		<visual>
			<geometry>
				<cylinder length="1.9169248928887492" radius="0.8523340855174112"/>
			</geometry>
		</visual>
		<collision>
			<geometry>
				<cylinder length="1.9169248928887492" radius="0.8523340855174112"/>
			</geometry>
		</collision>
		<inertial>
			<mass value="4.374966006870308"/>
			<inertia ixx="0.03" iyy="0.03" izz="0.03" ixy="0" ixz="0" iyx="0"/>
		</inertial>
	</link>
	<link name="33">
		<visual>
			<geometry>
				<cylinder length="1.3277542766093942" radius="0.29003324333393354"/>
			</geometry>
		</visual>
		<collision>
			<geometry>
				<cylinder length="1.3277542766093942" radius="0.29003324333393354"/>
			</geometry>
		</collision>
		<inertial>
			<mass value="0.35088365641710273"/>
			<inertia ixx="0.03" iyy="0.03" izz="0.03" ixy="0" ixz="0" iyx="0"/>
		</inertial>
	</link>
	<link name="44">
		<visual>
			<geometry>
				<cylinder length="0.012735360380922378" radius="0.8270030735154064"/>
			</geometry>
		</visual>
		<collision>
			<geometry>
				<cylinder length="0.012735360380922378" radius="0.8270030735154064"/>
			</geometry>
		</collision>
		<inertial>
			<mass value="0.02736373392582198"/>
			<inertia ixx="0.03" iyy="0.03" izz="0.03" ixy="0" ixz="0" iyx="0"/>
		</inertial>
	</link>
	<link name="45">
		<visual>
			<geometry>
				<cylinder length="0.012735360380922378" radius="0.8270030735154064"/>
			</geometry>
		</visual>
		<collision>
			<geometry>
				<cylinder length="0.012735360380922378" radius="0.8270030735154064"/>
			</geometry>
		</collision>
		<inertial>
			<mass value="0.02736373392582198"/>
			<inertia ixx="0.03" iyy="0.03" izz="0.03" ixy="0" ixz="0" iyx="0"/>
		</inertial>
	</link>
	<link name="36">
		<visual>
			<geometry>
				<cylinder length="1.3277542766093942" radius="0.29003324333393354"/>
			</geometry>
		</visual>
		<collision>
			<geometry>
				<cylinder length="1.3277542766093942" radius="0.29003324333393354"/>
			</geometry>
		</collision>
		<inertial>
			<mass value="0.35088365641710273"/>
			<inertia ixx="0.03" iyy="0.03" izz="0.03" ixy="0" ixz="0" iyx="0"/>
		</inertial>
	</link>
	<link name="47">
		<visual>
			<geometry>
				<cylinder length="0.012735360380922378" radius="0.8270030735154064"/>
			</geometry>
		</visual>
		<collision>
			<geometry>
				<cylinder length="0.012735360380922378" radius="0.8270030735154064"/>
			</geometry>
		</collision>
		<inertial>
			<mass value="0.02736373392582198"/>
			<inertia ixx="0.03" iyy="0.03" izz="0.03" ixy="0" ixz="0" iyx="0"/>
		</inertial>
	</link>
	<link name="48">
		<visual>
			<geometry>
				<cylinder length="0.012735360380922378" radius="0.8270030735154064"/>
			</geometry>
		</visual>
		<collision>
			<geometry>
				<cylinder length="0.012735360380922378" radius="0.8270030735154064"/>
			</geometry>
		</collision>
		<inertial>
			<mass value="0.02736373392582198"/>
			<inertia ixx="0.03" iyy="0.03" izz="0.03" ixy="0" ixz="0" iyx="0"/>
		</inertial>
	</link>
	<link name="39">
		<visual>
			<geometry>
				<cylinder length="1.3277542766093942" radius="0.29003324333393354"/>
			</geometry>
		</visual>
		<collision>
			<geometry>
				<cylinder length="1.3277542766093942" radius="0.29003324333393354"/>
			</geometry>
		</collision>
		<inertial>
			<mass value="0.35088365641710273"/>
			<inertia ixx="0.03" iyy="0.03" izz="0.03" ixy="0" ixz="0" iyx="0"/>
		</inertial>
	</link>
	<link name="410">
		<visual>
			<geometry>
				<cylinder length="0.012735360380922378" radius="0.8270030735154064"/>
			</geometry>
		</visual>
		<collision>
			<geometry>
				<cylinder length="0.012735360380922378" radius="0.8270030735154064"/>
			</geometry>
		</collision>
		<inertial>
			<mass value="0.02736373392582198"/>
			<inertia ixx="0.03" iyy="0.03" izz="0.03" ixy="0" ixz="0" iyx="0"/>
		</inertial>
	</link>
	<link name="411">
		<visual>
			<geometry>
				<cylinder length="0.012735360380922378" radius="0.8270030735154064"/>
			</geometry>
		</visual>
		<collision>
			<geometry>
				<cylinder length="0.012735360380922378" radius="0.8270030735154064"/>
			</geometry>
		</collision>
		<inertial>
			<mass value="0.02736373392582198"/>
			<inertia ixx="0.03" iyy="0.03" izz="0.03" ixy="0" ixz="0" iyx="0"/>
		</inertial>
	</link>
	<link name="212">
		<visual>
			<geometry>
				<cylinder length="1.9169248928887492" radius="0.8523340855174112"/>
			</geometry>
		</visual>
		<collision>
			<geometry>
				<cylinder length="1.9169248928887492" radius="0.8523340855174112"/>
			</geometry>
		</collision>
		<inertial>
			<mass value="4.374966006870308"/>
			<inertia ixx="0.03" iyy="0.03" izz="0.03" ixy="0" ixz="0" iyx="0"/>
		</inertial>
	</link>
	<link name="313">
		<visual>
			<geometry>
				<cylinder length="1.3277542766093942" radius="0.29003324333393354"/>
			</geometry>
		</visual>
		<collision>
			<geometry>
				<cylinder length="1.3277542766093942" radius="0.29003324333393354"/>
			</geometry>
		</collision>
		<inertial>
			<mass value="0.35088365641710273"/>
			<inertia ixx="0.03" iyy="0.03" izz="0.03" ixy="0" ixz="0" iyx="0"/>
		</inertial>
	</link>
	<link name="414">
		<visual>
			<geometry>
				<cylinder length="0.012735360380922378" radius="0.8270030735154064"/>
			</geometry>
		</visual>
		<collision>
			<geometry>
				<cylinder length="0.012735360380922378" radius="0.8270030735154064"/>
			</geometry>
		</collision>
		<inertial>
			<mass value="0.02736373392582198"/>
			<inertia ixx="0.03" iyy="0.03" izz="0.03" ixy="0" ixz="0" iyx="0"/>
		</inertial>
	</link>
	<link name="415">
		<visual>
			<geometry>
				<cylinder length="0.012735360380922378" radius="0.8270030735154064"/>
			</geometry>
		</visual>
		<collision>
			<geometry>
				<cylinder length="0.012735360380922378" radius="0.8270030735154064"/>
			</geometry>
		</collision>
		<inertial>
			<mass value="0.02736373392582198"/>
			<inertia ixx="0.03" iyy="0.03" izz="0.03" ixy="0" ixz="0" iyx="0"/>
		</inertial>
	</link>
	<link name="316">
		<visual>
			<geometry>
				<cylinder length="1.3277542766093942" radius="0.29003324333393354"/>
			</geometry>
		</visual>
		<collision>
			<geometry>
				<cylinder length="1.3277542766093942" radius="0.29003324333393354"/>
			</geometry>
		</collision>
		<inertial>
			<mass value="0.35088365641710273"/>
			<inertia ixx="0.03" iyy="0.03" izz="0.03" ixy="0" ixz="0" iyx="0"/>
		</inertial>
	</link>
	<link name="417">
		<visual>
			<geometry>
				<cylinder length="0.012735360380922378" radius="0.8270030735154064"/>
			</geometry>
		</visual>
		<collision>
			<geometry>
				<cylinder length="0.012735360380922378" radius="0.8270030735154064"/>
			</geometry>
		</collision>
		<inertial>
			<mass value="0.02736373392582198"/>
			<inertia ixx="0.03" iyy="0.03" izz="0.03" ixy="0" ixz="0" iyx="0"/>
		</inertial>
	</link>
	<link name="418">
		<visual>
			<geometry>
				<cylinder length="0.012735360380922378" radius="0.8270030735154064"/>
			</geometry>
		</visual>
		<collision>
			<geometry>
				<cylinder length="0.012735360380922378" radius="0.8270030735154064"/>
			</geometry>
		</collision>
		<inertial>
			<mass value="0.02736373392582198"/>
			<inertia ixx="0.03" iyy="0.03" izz="0.03" ixy="0" ixz="0" iyx="0"/>
		</inertial>
	</link>
	<link name="319">
		<visual>
			<geometry>
				<cylinder length="1.3277542766093942" radius="0.29003324333393354"/>
			</geometry>
		</visual>
		<collision>
			<geometry>
				<cylinder length="1.3277542766093942" radius="0.29003324333393354"/>
			</geometry>
		</collision>
		<inertial>
			<mass value="0.35088365641710273"/>
			<inertia ixx="0.03" iyy="0.03" izz="0.03" ixy="0" ixz="0" iyx="0"/>
		</inertial>
	</link>
	<link name="420">
		<visual>
			<geometry>
				<cylinder length="0.012735360380922378" radius="0.8270030735154064"/>
			</geometry>
		</visual>
		<collision>
			<geometry>
				<cylinder length="0.012735360380922378" radius="0.8270030735154064"/>
			</geometry>
		</collision>
		<inertial>
			<mass value="0.02736373392582198"/>
			<inertia ixx="0.03" iyy="0.03" izz="0.03" ixy="0" ixz="0" iyx="0"/>
		</inertial>
	</link>
	<link name="421">
		<visual>
			<geometry>
				<cylinder length="0.012735360380922378" radius="0.8270030735154064"/>
			</geometry>
		</visual>
		<collision>
			<geometry>
				<cylinder length="0.012735360380922378" radius="0.8270030735154064"/>
			</geometry>
		</collision>
		<inertial>
			<mass value="0.02736373392582198"/>
			<inertia ixx="0.03" iyy="0.03" izz="0.03" ixy="0" ixz="0" iyx="0"/>
		</inertial>
	</link>
	<link name="122">
		<visual>
			<geometry>
				<cylinder length="0.32081908219065847" radius="0.1284561824784013"/>
			</geometry>
		</visual>
		<collision>
			<geometry>
				<cylinder length="0.32081908219065847" radius="0.1284561824784013"/>
			</geometry>
		</collision>
		<inertial>
			<mass value="0.016631066011143343"/>
			<inertia ixx="0.03" iyy="0.03" izz="0.03" ixy="0" ixz="0" iyx="0"/>
		</inertial>
	</link>
	<link name="223">
		<visual>
			<geometry>
				<cylinder length="1.9169248928887492" radius="0.8523340855174112"/>
			</geometry>
		</visual>
		<collision>
			<geometry>
				<cylinder length="1.9169248928887492" radius="0.8523340855174112"/>
			</geometry>
		</collision>
		<inertial>
			<mass value="4.374966006870308"/>
			<inertia ixx="0.03" iyy="0.03" izz="0.03" ixy="0" ixz="0" iyx="0"/>
		</inertial>
	</link>
	<link name="324">
		<visual>
			<geometry>
				<cylinder length="1.3277542766093942" radius="0.29003324333393354"/>
			</geometry>
		</visual>
		<collision>
			<geometry>
				<cylinder length="1.3277542766093942" radius="0.29003324333393354"/>
			</geometry>
		</collision>
		<inertial>
			<mass value="0.35088365641710273"/>
			<inertia ixx="0.03" iyy="0.03" izz="0.03" ixy="0" ixz="0" iyx="0"/>
		</inertial>
	</link>
	<link name="425">
		<visual>
			<geometry>
				<cylinder length="0.012735360380922378" radius="0.8270030735154064"/>
			</geometry>
		</visual>
		<collision>
			<geometry>
				<cylinder length="0.012735360380922378" radius="0.8270030735154064"/>
			</geometry>
		</collision>
		<inertial>
			<mass value="0.02736373392582198"/>
			<inertia ixx="0.03" iyy="0.03" izz="0.03" ixy="0" ixz="0" iyx="0"/>
		</inertial>
	</link>
	<link name="426">
		<visual>
			<geometry>
				<cylinder length="0.012735360380922378" radius="0.8270030735154064"/>
			</geometry>
		</visual>
		<collision>
			<geometry>
				<cylinder length="0.012735360380922378" radius="0.8270030735154064"/>
			</geometry>
		</collision>
		<inertial>
			<mass value="0.02736373392582198"/>
			<inertia ixx="0.03" iyy="0.03" izz="0.03" ixy="0" ixz="0" iyx="0"/>
		</inertial>
	</link>
	<link name="327">
		<visual>
			<geometry>
				<cylinder length="1.3277542766093942" radius="0.29003324333393354"/>
			</geometry>
		</visual>
		<collision>
			<geometry>
				<cylinder length="1.3277542766093942" radius="0.29003324333393354"/>
			</geometry>
		</collision>
		<inertial>
			<mass value="0.35088365641710273"/>
			<inertia ixx="0.03" iyy="0.03" izz="0.03" ixy="0" ixz="0" iyx="0"/>
		</inertial>
	</link>
	<link name="428">
		<visual>
			<geometry>
				<cylinder length="0.012735360380922378" radius="0.8270030735154064"/>
			</geometry>
		</visual>
		<collision>
			<geometry>
				<cylinder length="0.012735360380922378" radius="0.8270030735154064"/>
			</geometry>
		</collision>
		<inertial>
			<mass value="0.02736373392582198"/>
			<inertia ixx="0.03" iyy="0.03" izz="0.03" ixy="0" ixz="0" iyx="0"/>
		</inertial>
	</link>
	<link name="429">
		<visual>
			<geometry>
				<cylinder length="0.012735360380922378" radius="0.8270030735154064"/>
			</geometry>
		</visual>
		<collision>
			<geometry>
				<cylinder length="0.012735360380922378" radius="0.8270030735154064"/>
			</geometry>
		</collision>
		<inertial>
			<mass value="0.02736373392582198"/>
			<inertia ixx="0.03" iyy="0.03" izz="0.03" ixy="0" ixz="0" iyx="0"/>
		</inertial>
	</link>
	<link name="330">
		<visual>
			<geometry>
				<cylinder length="1.3277542766093942" radius="0.29003324333393354"/>
			</geometry>
		</visual>
		<collision>
			<geometry>
				<cylinder length="1.3277542766093942" radius="0.29003324333393354"/>
			</geometry>
		</collision>
		<inertial>
			<mass value="0.35088365641710273"/>
			<inertia ixx="0.03" iyy="0.03" izz="0.03" ixy="0" ixz="0" iyx="0"/>
		</inertial>
	</link>
	<link name="431">
		<visual>
			<geometry>
				<cylinder length="0.012735360380922378" radius="0.8270030735154064"/>
			</geometry>
		</visual>
		<collision>
			<geometry>
				<cylinder length="0.012735360380922378" radius="0.8270030735154064"/>
			</geometry>
		</collision>
		<inertial>
			<mass value="0.02736373392582198"/>
			<inertia ixx="0.03" iyy="0.03" izz="0.03" ixy="0" ixz="0" iyx="0"/>
		</inertial>
	</link>
	<link name="432">
		<visual>
			<geometry>
				<cylinder length="0.012735360380922378" radius="0.8270030735154064"/>
			</geometry>
		</visual>
		<collision>
			<geometry>
				<cylinder length="0.012735360380922378" radius="0.8270030735154064"/>
			</geometry>
		</collision>
		<inertial>
			<mass value="0.02736373392582198"/>
			<inertia ixx="0.03" iyy="0.03" izz="0.03" ixy="0" ixz="0" iyx="0"/>
		</inertial>
	</link>
	<link name="233">
		<visual>
			<geometry>
				<cylinder length="1.9169248928887492" radius="0.8523340855174112"/>
			</geometry>
		</visual>
		<collision>
			<geometry>
				<cylinder length="1.9169248928887492" radius="0.8523340855174112"/>
			</geometry>
		</collision>
		<inertial>
			<mass value="4.374966006870308"/>
			<inertia ixx="0.03" iyy="0.03" izz="0.03" ixy="0" ixz="0" iyx="0"/>
		</inertial>
	</link>
	<link name="334">
		<visual>
			<geometry>
				<cylinder length="1.3277542766093942" radius="0.29003324333393354"/>
			</geometry>
		</visual>
		<collision>
			<geometry>
				<cylinder length="1.3277542766093942" radius="0.29003324333393354"/>
			</geometry>
		</collision>
		<inertial>
			<mass value="0.35088365641710273"/>
			<inertia ixx="0.03" iyy="0.03" izz="0.03" ixy="0" ixz="0" iyx="0"/>
		</inertial>
	</link>
	<link name="435">
		<visual>
			<geometry>
				<cylinder length="0.012735360380922378" radius="0.8270030735154064"/>
			</geometry>
		</visual>
		<collision>
			<geometry>
				<cylinder length="0.012735360380922378" radius="0.8270030735154064"/>
			</geometry>
		</collision>
		<inertial>
			<mass value="0.02736373392582198"/>
			<inertia ixx="0.03" iyy="0.03" izz="0.03" ixy="0" ixz="0" iyx="0"/>
		</inertial>
	</link>
	<link name="436">
		<visual>
			<geometry>
				<cylinder length="0.012735360380922378" radius="0.8270030735154064"/>
			</geometry>
		</visual>
		<collision>
			<geometry>
				<cylinder length="0.012735360380922378" radius="0.8270030735154064"/>
			</geometry>
		</collision>
		<inertial>
			<mass value="0.02736373392582198"/>
			<inertia ixx="0.03" iyy="0.03" izz="0.03" ixy="0" ixz="0" iyx="0"/>
		</inertial>
	</link>
	<link name="337">
		<visual>
			<geometry>
				<cylinder length="1.3277542766093942" radius="0.29003324333393354"/>
			</geometry>
		</visual>
		<collision>
			<geometry>
				<cylinder length="1.3277542766093942" radius="0.29003324333393354"/>
			</geometry>
		</collision>
		<inertial>
			<mass value="0.35088365641710273"/>
			<inertia ixx="0.03" iyy="0.03" izz="0.03" ixy="0" ixz="0" iyx="0"/>
		</inertial>
	</link>
	<link name="438">
		<visual>
			<geometry>
				<cylinder length="0.012735360380922378" radius="0.8270030735154064"/>
			</geometry>
		</visual>
		<collision>
			<geometry>
				<cylinder length="0.012735360380922378" radius="0.8270030735154064"/>
			</geometry>
		</collision>
		<inertial>
			<mass value="0.02736373392582198"/>
			<inertia ixx="0.03" iyy="0.03" izz="0.03" ixy="0" ixz="0" iyx="0"/>
		</inertial>
	</link>
	<link name="439">
		<visual>
			<geometry>
				<cylinder length="0.012735360380922378" radius="0.8270030735154064"/>
			</geometry>
		</visual>
		<collision>
			<geometry>
				<cylinder length="0.012735360380922378" radius="0.8270030735154064"/>
			</geometry>
		</collision>
		<inertial>
			<mass value="0.02736373392582198"/>
			<inertia ixx="0.03" iyy="0.03" izz="0.03" ixy="0" ixz="0" iyx="0"/>
		</inertial>
	</link>
	<link name="340">
		<visual>
			<geometry>
				<cylinder length="1.3277542766093942" radius="0.29003324333393354"/>
			</geometry>
		</visual>
		<collision>
			<geometry>
				<cylinder length="1.3277542766093942" radius="0.29003324333393354"/>
			</geometry>
		</collision>
		<inertial>
			<mass value="0.35088365641710273"/>
			<inertia ixx="0.03" iyy="0.03" izz="0.03" ixy="0" ixz="0" iyx="0"/>
		</inertial>
	</link>
	<link name="441">
		<visual>
			<geometry>
				<cylinder length="0.012735360380922378" radius="0.8270030735154064"/>
			</geometry>
		</visual>
		<collision>
			<geometry>
				<cylinder length="0.012735360380922378" radius="0.8270030735154064"/>
			</geometry>
		</collision>
		<inertial>
			<mass value="0.02736373392582198"/>
			<inertia ixx="0.03" iyy="0.03" izz="0.03" ixy="0" ixz="0" iyx="0"/>
		</inertial>
	</link>
	<link name="442">
		<visual>
			<geometry>
				<cylinder length="0.012735360380922378" radius="0.8270030735154064"/>
			</geometry>
		</visual>
		<collision>
			<geometry>
				<cylinder length="0.012735360380922378" radius="0.8270030735154064"/>
			</geometry>
		</collision>
		<inertial>
			<mass value="0.02736373392582198"/>
			<inertia ixx="0.03" iyy="0.03" izz="0.03" ixy="0" ixz="0" iyx="0"/>
		</inertial>
	</link>
	<joint name="11_to_0" type="revolute">
		<parent link="0"/>
		<child link="11"/>
		<axis xyz="1 0 0"/>
		<limit effort="1" upper="-3.1415" lower="3.1415" velocity="1"/>
		<origin rpy="10.946947917755876 4.186767556016323 4.305604338877434" xyz="0.5119903597292577 0.33004141252437713 0.7557924173577275"/>
	</joint>
	<joint name="22_to_11" type="revolute">
		<parent link="11"/>
		<child link="22"/>
		<axis xyz="0 1 0"/>
		<limit effort="1" upper="-3.1415" lower="3.1415" velocity="1"/>
		<origin rpy="9.006268995180783 2.044128836080429 1.750207413993473" xyz="0.4208722991634648 0.8530252952494786 0.3907072081987478"/>
	</joint>
	<joint name="33_to_22" type="revolute">
		<parent link="22"/>
		<child link="33"/>
		<axis xyz="1 0 0"/>
		<limit effort="1" upper="-3.1415" lower="3.1415" velocity="1"/>
		<origin rpy="8.885991104832222 1.4801097322781616 2.0170502611066468" xyz="0.6163980471625176 0.6768992431198676 0.9819536484517642"/>
	</joint>
	<joint name="44_to_33" type="revolute">
		<parent link="33"/>
		<child link="44"/>
		<axis xyz="0 1 0"/>
		<limit effort="1" upper="-3.1415" lower="3.1415" velocity="1"/>
		<origin rpy="10.65268422767284 2.905638901085572 4.773271544270561" xyz="0.30242507243658856 0.46482578691610954 0.526719959329766"/>
	</joint>
	<joint name="45_to_33" type="revolute">
		<parent link="33"/>
		<child link="45"/>
		<axis xyz="0 1 0"/>
		<limit effort="1" upper="-3.1415" lower="3.1415" velocity="1"/>
		<origin rpy="15.97902634150926 2.905638901085572 4.773271544270561" xyz="0.30242507243658856 0.46482578691610954 0.526719959329766"/>
	</joint>
	<joint name="36_to_22" type="revolute">
		<parent link="22"/>
		<child link="36"/>
		<axis xyz="1 0 0"/>
		<limit effort="1" upper="-3.1415" lower="3.1415" velocity="1"/>
		<origin rpy="13.328986657248333 1.4801097322781616 2.0170502611066468" xyz="0.6163980471625176 0.6768992431198676 0.9819536484517642"/>
	</joint>
	<joint name="47_to_36" type="revolute">
		<parent link="36"/>
		<child link="47"/>
		<axis xyz="0 1 0"/>
		<limit effort="1" upper="-3.1415" lower="3.1415" velocity="1"/>
		<origin rpy="10.65268422767284 2.905638901085572 4.773271544270561" xyz="0.30242507243658856 0.46482578691610954 0.526719959329766"/>
	</joint>
	<joint name="48_to_36" type="revolute">
		<parent link="36"/>
		<child link="48"/>
		<axis xyz="0 1 0"/>
		<limit effort="1" upper="-3.1415" lower="3.1415" velocity="1"/>
		<origin rpy="15.97902634150926 2.905638901085572 4.773271544270561" xyz="0.30242507243658856 0.46482578691610954 0.526719959329766"/>
	</joint>
	<joint name="39_to_22" type="revolute">
		<parent link="22"/>
		<child link="39"/>
		<axis xyz="1 0 0"/>
		<limit effort="1" upper="-3.1415" lower="3.1415" velocity="1"/>
		<origin rpy="17.771982209664444 1.4801097322781616 2.0170502611066468" xyz="0.6163980471625176 0.6768992431198676 0.9819536484517642"/>
	</joint>
	<joint name="410_to_39" type="revolute">
		<parent link="39"/>
		<child link="410"/>
		<axis xyz="0 1 0"/>
		<limit effort="1" upper="-3.1415" lower="3.1415" velocity="1"/>
		<origin rpy="10.65268422767284 2.905638901085572 4.773271544270561" xyz="0.30242507243658856 0.46482578691610954 0.526719959329766"/>
	</joint>
	<joint name="411_to_39" type="revolute">
		<parent link="39"/>
		<child link="411"/>
		<axis xyz="0 1 0"/>
		<limit effort="1" upper="-3.1415" lower="3.1415" velocity="1"/>
		<origin rpy="15.97902634150926 2.905638901085572 4.773271544270561" xyz="0.30242507243658856 0.46482578691610954 0.526719959329766"/>
	</joint>
	<joint name="212_to_11" type="revolute">
		<parent link="11"/>
		<child link="212"/>
		<axis xyz="0 1 0"/>
		<limit effort="1" upper="-3.1415" lower="3.1415" velocity="1"/>
		<origin rpy="13.509403492771174 2.044128836080429 1.750207413993473" xyz="0.4208722991634648 0.8530252952494786 0.3907072081987478"/>
	</joint>
	<joint name="313_to_212" type="revolute">
		<parent link="212"/>
		<child link="313"/>
		<axis xyz="1 0 0"/>
		<limit effort="1" upper="-3.1415" lower="3.1415" velocity="1"/>
		<origin rpy="8.885991104832222 1.4801097322781616 2.0170502611066468" xyz="0.6163980471625176 0.6768992431198676 0.9819536484517642"/>
	</joint>
	<joint name="414_to_313" type="revolute">
		<parent link="313"/>
		<child link="414"/>
		<axis xyz="0 1 0"/>
		<limit effort="1" upper="-3.1415" lower="3.1415" velocity="1"/>
		<origin rpy="10.65268422767284 2.905638901085572 4.773271544270561" xyz="0.30242507243658856 0.46482578691610954 0.526719959329766"/>
	</joint>
	<joint name="415_to_313" type="revolute">
		<parent link="313"/>
		<child link="415"/>
		<axis xyz="0 1 0"/>
		<limit effort="1" upper="-3.1415" lower="3.1415" velocity="1"/>
		<origin rpy="15.97902634150926 2.905638901085572 4.773271544270561" xyz="0.30242507243658856 0.46482578691610954 0.526719959329766"/>
	</joint>
	<joint name="316_to_212" type="revolute">
		<parent link="212"/>
		<child link="316"/>
		<axis xyz="1 0 0"/>
		<limit effort="1" upper="-3.1415" lower="3.1415" velocity="1"/>
		<origin rpy="13.328986657248333 1.4801097322781616 2.0170502611066468" xyz="0.6163980471625176 0.6768992431198676 0.9819536484517642"/>
	</joint>
	<joint name="417_to_316" type="revolute">
		<parent link="316"/>
		<child link="417"/>
		<axis xyz="0 1 0"/>
		<limit effort="1" upper="-3.1415" lower="3.1415" velocity="1"/>
		<origin rpy="10.65268422767284 2.905638901085572 4.773271544270561" xyz="0.30242507243658856 0.46482578691610954 0.526719959329766"/>
	</joint>
	<joint name="418_to_316" type="revolute">
		<parent link="316"/>
		<child link="418"/>
		<axis xyz="0 1 0"/>
		<limit effort="1" upper="-3.1415" lower="3.1415" velocity="1"/>
		<origin rpy="15.97902634150926 2.905638901085572 4.773271544270561" xyz="0.30242507243658856 0.46482578691610954 0.526719959329766"/>
	</joint>
	<joint name="319_to_212" type="revolute">
		<parent link="212"/>
		<child link="319"/>
		<axis xyz="1 0 0"/>
		<limit effort="1" upper="-3.1415" lower="3.1415" velocity="1"/>
		<origin rpy="17.771982209664444 1.4801097322781616 2.0170502611066468" xyz="0.6163980471625176 0.6768992431198676 0.9819536484517642"/>
	</joint>
	<joint name="420_to_319" type="revolute">
		<parent link="319"/>
		<child link="420"/>
		<axis xyz="0 1 0"/>
		<limit effort="1" upper="-3.1415" lower="3.1415" velocity="1"/>
		<origin rpy="10.65268422767284 2.905638901085572 4.773271544270561" xyz="0.30242507243658856 0.46482578691610954 0.526719959329766"/>
	</joint>
	<joint name="421_to_319" type="revolute">
		<parent link="319"/>
		<child link="421"/>
		<axis xyz="0 1 0"/>
		<limit effort="1" upper="-3.1415" lower="3.1415" velocity="1"/>
		<origin rpy="15.97902634150926 2.905638901085572 4.773271544270561" xyz="0.30242507243658856 0.46482578691610954 0.526719959329766"/>
	</joint>
	<joint name="122_to_0" type="revolute">
		<parent link="0"/>
		<child link="122"/>
		<axis xyz="1 0 0"/>
		<limit effort="1" upper="-3.1415" lower="3.1415" velocity="1"/>
		<origin rpy="16.420421876633814 4.186767556016323 4.305604338877434" xyz="0.5119903597292577 0.33004141252437713 0.7557924173577275"/>
	</joint>
	<joint name="223_to_122" type="revolute">
		<parent link="122"/>
		<child link="223"/>
		<axis xyz="0 1 0"/>
		<limit effort="1" upper="-3.1415" lower="3.1415" velocity="1"/>
		<origin rpy="9.006268995180783 2.044128836080429 1.750207413993473" xyz="0.4208722991634648 0.8530252952494786 0.3907072081987478"/>
	</joint>
	<joint name="324_to_223" type="revolute">
		<parent link="223"/>
		<child link="324"/>
		<axis xyz="1 0 0"/>
		<limit effort="1" upper="-3.1415" lower="3.1415" velocity="1"/>
		<origin rpy="8.885991104832222 1.4801097322781616 2.0170502611066468" xyz="0.6163980471625176 0.6768992431198676 0.9819536484517642"/>
	</joint>
	<joint name="425_to_324" type="revolute">
		<parent link="324"/>
		<child link="425"/>
		<axis xyz="0 1 0"/>
		<limit effort="1" upper="-3.1415" lower="3.1415" velocity="1"/>
		<origin rpy="10.65268422767284 2.905638901085572 4.773271544270561" xyz="0.30242507243658856 0.46482578691610954 0.526719959329766"/>
	</joint>
	<joint name="426_to_324" type="revolute">
		<parent link="324"/>
		<child link="426"/>
		<axis xyz="0 1 0"/>
		<limit effort="1" upper="-3.1415" lower="3.1415" velocity="1"/>
		<origin rpy="15.97902634150926 2.905638901085572 4.773271544270561" xyz="0.30242507243658856 0.46482578691610954 0.526719959329766"/>
	</joint>
	<joint name="327_to_223" type="revolute">
		<parent link="223"/>
		<child link="327"/>
		<axis xyz="1 0 0"/>
		<limit effort="1" upper="-3.1415" lower="3.1415" velocity="1"/>
		<origin rpy="13.328986657248333 1.4801097322781616 2.0170502611066468" xyz="0.6163980471625176 0.6768992431198676 0.9819536484517642"/>
	</joint>
	<joint name="428_to_327" type="revolute">
		<parent link="327"/>
		<child link="428"/>
		<axis xyz="0 1 0"/>
		<limit effort="1" upper="-3.1415" lower="3.1415" velocity="1"/>
		<origin rpy="10.65268422767284 2.905638901085572 4.773271544270561" xyz="0.30242507243658856 0.46482578691610954 0.526719959329766"/>
	</joint>
	<joint name="429_to_327" type="revolute">
		<parent link="327"/>
		<child link="429"/>
		<axis xyz="0 1 0"/>
		<limit effort="1" upper="-3.1415" lower="3.1415" velocity="1"/>
		<origin rpy="15.97902634150926 2.905638901085572 4.773271544270561" xyz="0.30242507243658856 0.46482578691610954 0.526719959329766"/>
	</joint>
	<joint name="330_to_223" type="revolute">
		<parent link="223"/>
		<child link="330"/>
		<axis xyz="1 0 0"/>
		<limit effort="1" upper="-3.1415" lower="3.1415" velocity="1"/>
		<origin rpy="17.771982209664444 1.4801097322781616 2.0170502611066468" xyz="0.6163980471625176 0.6768992431198676 0.9819536484517642"/>
	</joint>
	<joint name="431_to_330" type="revolute">
		<parent link="330"/>
		<child link="431"/>
		<axis xyz="0 1 0"/>
		<limit effort="1" upper="-3.1415" lower="3.1415" velocity="1"/>
		<origin rpy="10.65268422767284 2.905638901085572 4.773271544270561" xyz="0.30242507243658856 0.46482578691610954 0.526719959329766"/>
	</joint>
	<joint name="432_to_330" type="revolute">
		<parent link="330"/>
		<child link="432"/>
		<axis xyz="0 1 0"/>
		<limit effort="1" upper="-3.1415" lower="3.1415" velocity="1"/>
		<origin rpy="15.97902634150926 2.905638901085572 4.773271544270561" xyz="0.30242507243658856 0.46482578691610954 0.526719959329766"/>
	</joint>
	<joint name="233_to_122" type="revolute">
		<parent link="122"/>
		<child link="233"/>
		<axis xyz="0 1 0"/>
		<limit effort="1" upper="-3.1415" lower="3.1415" velocity="1"/>
		<origin rpy="13.509403492771174 2.044128836080429 1.750207413993473" xyz="0.4208722991634648 0.8530252952494786 0.3907072081987478"/>
	</joint>
	<joint name="334_to_233" type="revolute">
		<parent link="233"/>
		<child link="334"/>
		<axis xyz="1 0 0"/>
		<limit effort="1" upper="-3.1415" lower="3.1415" velocity="1"/>
		<origin rpy="8.885991104832222 1.4801097322781616 2.0170502611066468" xyz="0.6163980471625176 0.6768992431198676 0.9819536484517642"/>
	</joint>
	<joint name="435_to_334" type="revolute">
		<parent link="334"/>
		<child link="435"/>
		<axis xyz="0 1 0"/>
		<limit effort="1" upper="-3.1415" lower="3.1415" velocity="1"/>
		<origin rpy="10.65268422767284 2.905638901085572 4.773271544270561" xyz="0.30242507243658856 0.46482578691610954 0.526719959329766"/>
	</joint>
	<joint name="436_to_334" type="revolute">
		<parent link="334"/>
		<child link="436"/>
		<axis xyz="0 1 0"/>
		<limit effort="1" upper="-3.1415" lower="3.1415" velocity="1"/>
		<origin rpy="15.97902634150926 2.905638901085572 4.773271544270561" xyz="0.30242507243658856 0.46482578691610954 0.526719959329766"/>
	</joint>
	<joint name="337_to_233" type="revolute">
		<parent link="233"/>
		<child link="337"/>
		<axis xyz="1 0 0"/>
		<limit effort="1" upper="-3.1415" lower="3.1415" velocity="1"/>
		<origin rpy="13.328986657248333 1.4801097322781616 2.0170502611066468" xyz="0.6163980471625176 0.6768992431198676 0.9819536484517642"/>
	</joint>
	<joint name="438_to_337" type="revolute">
		<parent link="337"/>
		<child link="438"/>
		<axis xyz="0 1 0"/>
		<limit effort="1" upper="-3.1415" lower="3.1415" velocity="1"/>
		<origin rpy="10.65268422767284 2.905638901085572 4.773271544270561" xyz="0.30242507243658856 0.46482578691610954 0.526719959329766"/>
	</joint>
	<joint name="439_to_337" type="revolute">
		<parent link="337"/>
		<child link="439"/>
		<axis xyz="0 1 0"/>
		<limit effort="1" upper="-3.1415" lower="3.1415" velocity="1"/>
		<origin rpy="15.97902634150926 2.905638901085572 4.773271544270561" xyz="0.30242507243658856 0.46482578691610954 0.526719959329766"/>
	</joint>
	<joint name="340_to_233" type="revolute">
		<parent link="233"/>
		<child link="340"/>
		<axis xyz="1 0 0"/>
		<limit effort="1" upper="-3.1415" lower="3.1415" velocity="1"/>
		<origin rpy="17.771982209664444 1.4801097322781616 2.0170502611066468" xyz="0.6163980471625176 0.6768992431198676 0.9819536484517642"/>
	</joint>
	<joint name="441_to_340" type="revolute">
		<parent link="340"/>
		<child link="441"/>
		<axis xyz="0 1 0"/>
		<limit effort="1" upper="-3.1415" lower="3.1415" velocity="1"/>
		<origin rpy="10.65268422767284 2.905638901085572 4.773271544270561" xyz="0.30242507243658856 0.46482578691610954 0.526719959329766"/>
	</joint>
	<joint name="442_to_340" type="revolute">
		<parent link="340"/>
		<child link="442"/>
		<axis xyz="0 1 0"/>
		<limit effort="1" upper="-3.1415" lower="3.1415" velocity="1"/>
		<origin rpy="15.97902634150926 2.905638901085572 4.773271544270561" xyz="0.30242507243658856 0.46482578691610954 0.526719959329766"/>
	</joint>
</robot>
